<mujoco model="box">
    <include file="./common/visual.xml"/>
    <include file="./common/skybox.xml"/>
    <include file="./common/materials.xml"/>

    <option timestep="0.02">
        <flag contact="disable" energy="enable"/>
    </option>

    <worldbody>
        <light name="light" pos="0 0 2"/>
        <geom name="floor" size="2 2 .2" type="plane" material="grid"/>
        <camera name="fixed" pos="0 -1.5 2" xyaxes='1 0 0 0 1 1'/>
        <camera name="lookat" mode="targetbodycom" target="base" pos="0 -1.5 2"/>
        <body name="base" pos="0 0 1">
            <joint name="hinge_1" type="hinge" axis="1 0 0"  damping="0.1"/>
            <joint name="hinge_2" type="hinge" axis="0 1 0"  damping="0.1"/>
            <joint name="hinge_3" type="hinge" axis="0 0 1"  damping="0.1"/>
            <geom name="base" material="self" type="box" pos="0 0 0" size="0.3 0.3 0.3" mass="1"/>
        </body>
    </worldbody>

    <actuator>
        <motor name="torque_1" joint="hinge_1" gear="1" ctrlrange="-1 1" ctrllimited="true"/>
        <motor name="torque_2" joint="hinge_2" gear="1" ctrlrange="-1 1" ctrllimited="true"/>
        <motor name="torque_3" joint="hinge_3" gear="1" ctrlrange="-1 1" ctrllimited="true"/>
    </actuator>
</mujoco>