<mujoco model="ellipsoid">
    <include file="./common/visual.xml"/>
    <include file="./common/skybox.xml"/>
    <include file="./common/materials.xml"/>

    <option timestep="0.01">
        <flag contact="disable" energy="disable"/>
    </option>

    <worldbody>
        <light name="light" pos="0 0 2"/>
        <geom name="floor" size="2 2 .2" type="plane" material="grid"/>
        <camera name="fixed" pos="0 -1.5 2" xyaxes='1 0 0 0 1 1'/>
        <camera name="lookat" mode="targetbodycom" target="base" pos="0 -1.5 2"/>
        <body name="base" pos="0 0 1">
            <joint name="ball_1" type="ball" damping="0.05"/>
            <geom name="base" material="self" type="ellipsoid" pos="0 0 0" size="0.2 0.4 0.5" mass="1"/>
        </body>
    </worldbody>

    <actuator>
        <motor name="ball_motor_1" joint="ball_1" gear=".1 0 0" ctrlrange="-1 1" ctrllimited="true"/>
        <motor name="ball_motor_2" joint="ball_1" gear="0 .1 0" ctrlrange="-1 1" ctrllimited="true"/>
        <motor name="ball_motor_3" joint="ball_1" gear="0 0 .1" ctrlrange="-1 1" ctrllimited="true"/>
    </actuator>
</mujoco>